Workbook
Name SegmentaçãodeDados_Causa_Raiz: #N/A
Name SegmentaçãodeDados_Data: #N/A
Name SegmentaçãodeDados_Data1: #N/A
Name SegmentaçãodeDados_Data2: #N/A
Name SegmentaçãodeDados_Setor: #N/A
Name SegmentaçãodeDados_Turno: #N/A

Sheet BD_PROD
B6: Data | C6: Meta da Produção | D6: Início Start Fábrica | E6: Início F1 | F6: Início F2 | G6: Fim F1 | H6: Fim F2 | I6: Início do Ensaque 1 | J6: Fim Ensaque 1 | K6: Início Ensaque 2 | L6: Fim Ensaque 2 | M6: Qtd Produzida | N6: Tonelada/h | O6: Prod Média | P6: Tempo Prod F1 | Q6: Tempo Prod F2 | R6: Tempo Médio Produção Fornos | S6: Paradas N prog F1 | T6: Paradas N prog F2 | U6: Total Paradas N prog | V6: Média Paradas n prog | W6: Produtividade Ens 1 | X6: Prod Ens 2 | Y6: Tempo Start L1 | Z6: TempoStart L2 | AA6: Média de Start | AB6: Tempo Parado | AC6: Carga Horária
B7: 46055 | C7: 61061 | D7: 0.875 | E7: 0.03125 | F7: 0.98888889 | G7: 0.70277778 | H7: 0.67916667 | I7: 0.03125 | J7: 0.68055556 | K7: 0.99027778 | L7: 0.66111111 | M7: 43500 | N7: =IFERROR(M7/(O7*24), " ") -> 2745.9232 | O7: =(X7+W7)/2 -> 0.66006944 | P7: =MOD(BD_PROD!$G7-BD_PROD!$E7,1) -> 0.67152778 | Q7: =MOD(BD_PROD!$H7-BD_PROD!$F7,1) -> 0.69027778 | R7: =(Q7+P7)/2 -> 0.68090278 | S7: =SUMIFS(BD_PARADAS[Tempo],BD_PARADAS[[Data ]],BD_PROD!$B7,BD_PARADAS[Setor],"Forno 1") + SUMIFS(BD_PARADAS[Tempo],BD_PARADAS[[Data ]],BD_PROD!$B7,BD_PARADAS[Setor],"Ensaque 1") -> 0 | T7: =SUMIFS(BD_PARADAS[Tempo],BD_PARADAS[[Data ]],BD_PROD!$B7,BD_PARADAS[Setor],"Forno 2") + SUMIFS(BD_PARADAS[Tempo],BD_PARADAS[[Data ]],BD_PROD!$B7,BD_PARADAS[Setor],"Ensaque 2") -> 0.045138889 | U7: =T7+S7 -> 0.045138889 | V7: =U7/2 -> 0.022569444 | W7: =MOD(J7-I7,1) -> 0.64930556 | X7: =MOD(L7-K7,1) -> 0.67083333 | Y7: =MOD(I7-D7,1) -> 0.15625 | Z7: =MOD(K7-D7,1) -> 0.11527778 | AA7: =(Z7+Y7)/2 -> 0.13576389 | AB7: =AA7+V7 -> 0.15833333 | AC7: =BD_PROD!$AB7+BD_PROD!$O7 -> 0.81840278
B8: 46056 | C8: 58058 | D8: 0.875 | E8: 0.94444444 | F8: 0.9375 | G8: 0.38194444 | H8: 0.68055556 | I8: 0.94513889 | J8: 0.38194444 | K8: 0.93819444 | L8: 0.68125 | M8: 44500 | N8: =IFERROR(M8/(O8*24), " ") -> 3143.0253 | O8: =(X8+W8)/2 -> 0.58993056 | P8: =MOD(BD_PROD!$G8-BD_PROD!$E8,1) -> 0.4375 | Q8: =MOD(BD_PROD!$H8-BD_PROD!$F8,1) -> 0.74305556 | R8: =(Q8+P8)/2 -> 0.59027778 | S8: =SUMIFS(BD_PARADAS[Tempo],BD_PARADAS[[Data ]],BD_PROD!$B8,BD_PARADAS[Setor],"Forno 1") + SUMIFS(BD_PARADAS[Tempo],BD_PARADAS[[Data ]],BD_PROD!$B8,BD_PARADAS[Setor],"Ensaque 1") -> 0.39097222 | T8: =SUMIFS(BD_PARADAS[Tempo],BD_PARADAS[[Data ]],BD_PROD!$B8,BD_PARADAS[Setor],"Forno 2") + SUMIFS(BD_PARADAS[Tempo],BD_PARADAS[[Data ]],BD_PROD!$B8,BD_PARADAS[Setor],"Ensaque 2") -> 0 | U8: =T8+S8 -> 0.39097222 | V8: =U8/2 -> 0.19548611 | W8: =MOD(J8-I8,1) -> 0.43680556 | X8: =MOD(L8-K8,1) -> 0.74305556 | Y8: =MOD(I8-D8,1) -> 0.070138889 | Z8: =MOD(K8-D8,1) -> 0.063194444 | AA8: =(Z8+Y8)/2 -> 0.066666667 | AB8: =AA8+V8 -> 0.26215278 | AC8: =BD_PROD!$AB8+BD_PROD!$O8 -> 0.85208333
B9: 46057 | C9: 57921 | D9: 0.875 | E9: 0.94791667 | F9: 0.94097222 | G9: 0.68402778 | H9: 0.68194444 | I9: 0.94861111 | J9: 0.6625 | K9: 0.94166667 | L9: 0.66666667 | M9: 51300 | N9: =IFERROR(M9/(O9*24), " ") -> 2971.0425 | O9: =(X9+W9)/2 -> 0.71944444 | P9: =MOD(BD_PROD!$G9-BD_PROD!$E9,1) -> 0.73611111 | Q9: =MOD(BD_PROD!$H9-BD_PROD!$F9,1) -> 0.74097222 | R9: =(Q9+P9)/2 -> 0.73854167 | S9: =SUMIFS(BD_PARADAS[Tempo],BD_PARADAS[[Data ]],BD_PROD!$B9,BD_PARADAS[Setor],"Forno 1") + SUMIFS(BD_PARADAS[Tempo],BD_PARADAS[[Data ]],BD_PROD!$B9,BD_PARADAS[Setor],"Ensaque 1") -> 0 | T9: =SUMIFS(BD_PARADAS[Tempo],BD_PARADAS[[Data ]],BD_PROD!$B9,BD_PARADAS[Setor],"Forno 2") + SUMIFS(BD_PARADAS[Tempo],BD_PARADAS[[Data ]],BD_PROD!$B9,BD_PARADAS[Setor],"Ensaque 2") -> 0 | U9: =T9+S9 -> 0 | V9: =U9/2 -> 0 | W9: =MOD(J9-I9,1) -> 0.71388889 | X9: =MOD(L9-K9,1) -> 0.725 | Y9: =MOD(I9-D9,1) -> 0.073611111 | Z9: =MOD(K9-D9,1) -> 0.066666667 | AA9: =(Z9+Y9)/2 -> 0.070138889 | AB9: =AA9+V9 -> 0.070138889 | AC9: =BD_PROD!$AB9+BD_PROD!$O9 -> 0.78958333
B10: 46058 | C10: 66277 | D10: 0.875 | E10: 0.94305556 | F10: 0.94513889 | G10: 0.68888889 | H10: 0.72083333 | I10: 0.94444444 | J10: 0.72222222 | K10: 0.94583333 | L10: 0.675 | M10: 67150 | N10: =IFERROR(M10/(O10*24), " ") -> 3713.3641 | O10: =(X10+W10)/2 -> 0.75347222 | P10: =MOD(BD_PROD!$G10-BD_PROD!$E10,1) -> 0.74583333 | Q10: =MOD(BD_PROD!$H10-BD_PROD!$F10,1) -> 0.77569444 | R10: =(Q10+P10)/2 -> 0.76076389 | S10: =SUMIFS(BD_PARADAS[Tempo],BD_PARADAS[[Data ]],BD_PROD!$B10,BD_PARADAS[Setor],"Forno 1") + SUMIFS(BD_PARADAS[Tempo],BD_PARADAS[[Data ]],BD_PROD!$B10,BD_PARADAS[Setor],"Ensaque 1") -> 0.0048611111 | T10: =SUMIFS(BD_PARADAS[Tempo],BD_PARADAS[[Data ]],BD_PROD!$B10,BD_PARADAS[Setor],"Forno 2") + SUMIFS(BD_PARADAS[Tempo],BD_PARADAS[[Data ]],BD_PROD!$B10,BD_PARADAS[Setor],"Ensaque 2") -> 0.015277778 | U10: =T10+S10 -> 0.020138889 | V10: =U10/2 -> 0.010069444 | W10: =MOD(J10-I10,1) -> 0.77777778 | X10: =MOD(L10-K10,1) -> 0.72916667 | Y10: =MOD(I10-D10,1) -> 0.069444444 | Z10: =MOD(K10-D10,1) -> 0.070833333 | AA10: =(Z10+Y10)/2 -> 0.070138889 | AB10: =AA10+V10 -> 0.080208333 | AC10: =BD_PROD!$AB10+BD_PROD!$O10 -> 0.83368056
B11: 46059 | C11: 35743 | D11: 0.875 | E11: 0.94722222 | F11: 0.94236111 | G11: 0.35416667 | H11: 0.35416667 | I11: 0.94791667 | J11: 0.35763889 | K11: 0.94305556 | L11: 0.35763889 | M11: 33700 | N11: =IFERROR(M11/(O11*24), " ") -> 3406.9082 | O11: =(X11+W11)/2 -> 0.41215278 | P11: =MOD(BD_PROD!$G11-BD_PROD!$E11,1) -> 0.40694444 | Q11: =MOD(BD_PROD!$H11-BD_PROD!$F11,1) -> 0.41180556 | R11: =(Q11+P11)/2 -> 0.409375 | S11: =SUMIFS(BD_PARADAS[Tempo],BD_PARADAS[[Data ]],BD_PROD!$B11,BD_PARADAS[Setor],"Forno 1") + SUMIFS(BD_PARADAS[Tempo],BD_PARADAS[[Data ]],BD_PROD!$B11,BD_PARADAS[Setor],"Ensaque 1") -> 0.0034722222 | T11: =SUMIFS(BD_PARADAS[Tempo],BD_PARADAS[[Data ]],BD_PROD!$B11,BD_PARADAS[Setor],"Forno 2") + SUMIFS(BD_PARADAS[Tempo],BD_PARADAS[[Data ]],BD_PROD!$B11,BD_PARADAS[Setor],"Ensaque 2") -> 0.0034722222 | U11: =T11+S11 -> 0.0069444444 | V11: =U11/2 -> 0.0034722222 | W11: =MOD(J11-I11,1) -> 0.40972222 | X11: =MOD(L11-K11,1) -> 0.41458333 | Y11: =MOD(I11-D11,1) -> 0.072916667 | Z11: =MOD(K11-D11,1) -> 0.068055556 | AA11: =(Z11+Y11)/2 -> 0.070486111 | AB11: =AA11+V11 -> 0.073958333 | AC11: =BD_PROD!$AB11+BD_PROD!$O11 -> 0.48611111
B12: 46062 | C12: 56282 | D12: 0.875 | E12: 0.95833333 | F12: 0.94444444 | G12: 0.71666667 | H12: 0.70277778 | I12: 0.95972222 | J12: 0.70625 | K12: 0.94583333 | L12: 0.66805556 | M12: 46800 | N12: =IFERROR(M12/(O12*24), " ") -> 2655.3191 | O12: =(X12+W12)/2 -> 0.734375 | P12: =MOD(BD_PROD!$G12-BD_PROD!$E12,1) -> 0.75833333 | Q12: =MOD(BD_PROD!$H12-BD_PROD!$F12,1) -> 0.75833333 | R12: =(Q12+P12)/2 -> 0.75833333 | S12: =SUMIFS(BD_PARADAS[Tempo],BD_PARADAS[[Data ]],BD_PROD!$B12,BD_PARADAS[Setor],"Forno 1") + SUMIFS(BD_PARADAS[Tempo],BD_PARADAS[[Data ]],BD_PROD!$B12,BD_PARADAS[Setor],"Ensaque 1") -> 0.083333333 | T12: =SUMIFS(BD_PARADAS[Tempo],BD_PARADAS[[Data ]],BD_PROD!$B12,BD_PARADAS[Setor],"Forno 2") + SUMIFS(BD_PARADAS[Tempo],BD_PARADAS[[Data ]],BD_PROD!$B12,BD_PARADAS[Setor],"Ensaque 2") -> 0 | U12: =T12+S12 -> 0.083333333 | V12: =U12/2 -> 0.041666667 | W12: =MOD(J12-I12,1) -> 0.74652778 | X12: =MOD(L12-K12,1) -> 0.72222222 | Y12: =MOD(I12-D12,1) -> 0.084722222 | Z12: =MOD(K12-D12,1) -> 0.070833333 | AA12: =(Z12+Y12)/2 -> 0.077777778 | AB12: =AA12+V12 -> 0.11944444 | AC12: =BD_PROD!$AB12+BD_PROD!$O12 -> 0.85381944
B13: 46063 | C13: 54542 | D13: 0.875 | E13: 0.94791667 | F13: 0.94097222 | G13: 0.70416667 | H13: 0.70416667 | I13: 0.94861111 | J13: 0.69791667 | K13: 0.94236111 | L13: 0.68402778 | M13: 52350 | N13: =IFERROR(M13/(O13*24), " ") -> 2925.9432 | O13: =(X13+W13)/2 -> 0.74548611 | P13: =MOD(BD_PROD!$G13-BD_PROD!$E13,1) -> 0.75625 | Q13: =MOD(BD_PROD!$H13-BD_PROD!$F13,1) -> 0.76319444 | R13: =(Q13+P13)/2 -> 0.75972222 | S13: =SUMIFS(BD_PARADAS[Tempo],BD_PARADAS[[Data ]],BD_PROD!$B13,BD_PARADAS[Setor],"Forno 1") + SUMIFS(BD_PARADAS[Tempo],BD_PARADAS[[Data ]],BD_PROD!$B13,BD_PARADAS[Setor],"Ensaque 1") -> 0 | T13: =SUMIFS(BD_PARADAS[Tempo],BD_PARADAS[[Data ]],BD_PROD!$B13,BD_PARADAS[Setor],"Forno 2") + SUMIFS(BD_PARADAS[Tempo],BD_PARADAS[[Data ]],BD_PROD!$B13,BD_PARADAS[Setor],"Ensaque 2") -> 0 | U13: =T13+S13 -> 0 | V13: =U13/2 -> 0 | W13: =MOD(J13-I13,1) -> 0.74930556 | X13: =MOD(L13-K13,1) -> 0.74166667 | Y13: =MOD(I13-D13,1) -> 0.073611111 | Z13: =MOD(K13-D13,1) -> 0.067361111 | AA13: =(Z13+Y13)/2 -> 0.070486111 | AB13: =AA13+V13 -> 0.070486111 | AC13: =BD_PROD!$AB13+BD_PROD!$O13 -> 0.81597222
B14: 46064 | C14: 54542 | D14: 0.875 | E14: 0.94791667 | F14: 0.9375 | G14: 0.70486111 | H14: 0.70138889 | I14: 0.94861111 | J14: 0.70069444 | K14: 0.93888889 | L14: 0.68958333 | M14: 53150 | N14: =IFERROR(M14/(O14*24), " ") -> 2947.3198 | O14: =(X14+W14)/2 -> 0.75138889 | P14: =MOD(BD_PROD!$G14-BD_PROD!$E14,1) -> 0.75694444 | Q14: =MOD(BD_PROD!$H14-BD_PROD!$F14,1) -> 0.76388889 | R14: =(Q14+P14)/2 -> 0.76041667 | S14: =SUMIFS(BD_PARADAS[Tempo],BD_PARADAS[[Data ]],BD_PROD!$B14,BD_PARADAS[Setor],"Forno 1") + SUMIFS(BD_PARADAS[Tempo],BD_PARADAS[[Data ]],BD_PROD!$B14,BD_PARADAS[Setor],"Ensaque 1") -> 0.052083333 | T14: =SUMIFS(BD_PARADAS[Tempo],BD_PARADAS[[Data ]],BD_PROD!$B14,BD_PARADAS[Setor],"Forno 2") + SUMIFS(BD_PARADAS[Tempo],BD_PARADAS[[Data ]],BD_PROD!$B14,BD_PARADAS[Setor],"Ensaque 2") -> 0 | U14: =T14+S14 -> 0.052083333 | V14: =U14/2 -> 0.026041667 | W14: =MOD(J14-I14,1) -> 0.75208333 | X14: =MOD(L14-K14,1) -> 0.75069444 | Y14: =MOD(I14-D14,1) -> 0.073611111 | Z14: =MOD(K14-D14,1) -> 0.063888889 | AA14: =(Z14+Y14)/2 -> 0.06875 | AB14: =AA14+V14 -> 0.094791667 | AC14: =BD_PROD!$AB14+BD_PROD!$O14 -> 0.84618056
B15: 46065 | C15: 54542 | D15: 0.875 | E15: 0.94097222 | F15: 0.94097222 | G15: 0.7 | H15: 0.70625 | I15: 0.94236111 | J15: 0.45277778 | K15: 0.94166667 | L15: 0.69305556 | M15: 46250 | N15: =IFERROR(M15/(O15*24), " ") -> 3054.4854 | O15: =(X15+W15)/2 -> 0.63090278 | P15: =MOD(BD_PROD!$G15-BD_PROD!$E15,1) -> 0.75902778 | Q15: =MOD(BD_PROD!$H15-BD_PROD!$F15,1) -> 0.76527778 | R15: =(Q15+P15)/2 -> 0.76215278 | S15: =SUMIFS(BD_PARADAS[Tempo],BD_PARADAS[[Data ]],BD_PROD!$B15,BD_PARADAS[Setor],"Forno 1") + SUMIFS(BD_PARADAS[Tempo],BD_PARADAS[[Data ]],BD_PROD!$B15,BD_PARADAS[Setor],"Ensaque 1") -> 0.23958333 | T15: =SUMIFS(BD_PARADAS[Tempo],BD_PARADAS[[Data ]],BD_PROD!$B15,BD_PARADAS[Setor],"Forno 2") + SUMIFS(BD_PARADAS[Tempo],BD_PARADAS[[Data ]],BD_PROD!$B15,BD_PARADAS[Setor],"Ensaque 2") -> 0 | U15: =T15+S15 -> 0.23958333 | V15: =U15/2 -> 0.11979167 | W15: =MOD(J15-I15,1) -> 0.51041667 | X15: =MOD(L15-K15,1) -> 0.75138889 | Y15: =MOD(I15-D15,1) -> 0.067361111 | Z15: =MOD(K15-D15,1) -> 0.066666667 | AA15: =(Z15+Y15)/2 -> 0.067013889 | AB15: =AA15+V15 -> 0.18680556 | AC15: =BD_PROD!$AB15+BD_PROD!$O15 -> 0.81770833
B16: 46066 | C16: 30195 | D16: 0.875 | E16: 0.94097222 | F16: 0.94097222 | G16: 0.35138889 | H16: 0.35486111 | I16: 0.94305556 | J16: 0.36111111 | K16: 0.94236111 | L16: 0.35208333 | M16: 30150 | N16: =IFERROR(M16/(O16*24), " ") -> 3035.2349 | O16: =(X16+W16)/2 -> 0.41388889 | P16: =MOD(BD_PROD!$G16-BD_PROD!$E16,1) -> 0.41041667 | Q16: =MOD(BD_PROD!$H16-BD_PROD!$F16,1) -> 0.41388889 | R16: =(Q16+P16)/2 -> 0.41215278 | S16: =SUMIFS(BD_PARADAS[Tempo],BD_PARADAS[[Data ]],BD_PROD!$B16,BD_PARADAS[Setor],"Forno 1") + SUMIFS(BD_PARADAS[Tempo],BD_PARADAS[[Data ]],BD_PROD!$B16,BD_PARADAS[Setor],"Ensaque 1") -> 0 | T16: =SUMIFS(BD_PARADAS[Tempo],BD_PARADAS[[Data ]],BD_PROD!$B16,BD_PARADAS[Setor],"Forno 2") + SUMIFS(BD_PARADAS[Tempo],BD_PARADAS[[Data ]],BD_PROD!$B16,BD_PARADAS[Setor],"Ensaque 2") -> 0 | U16: =T16+S16 -> 0 | V16: =U16/2 -> 0 | W16: =MOD(J16-I16,1) -> 0.41805556 | X16: =MOD(L16-K16,1) -> 0.40972222 | Y16: =MOD(I16-D16,1) -> 0.068055556 | Z16: =MOD(K16-D16,1) -> 0.067361111 | AA16: =(Z16+Y16)/2 -> 0.067708333 | AB16: =AA16+V16 -> 0.067708333 | AC16: =BD_PROD!$AB16+BD_PROD!$O16 -> 0.48159722
B17: 46069 | C17: 61061 | D17: 0.875 | E17: 0.95486111 | F17: 0.97222222 | G17: 0.69930556 | H17: 0.72013889 | I17: 0.95555556 | J17: 0.66666667 | K17: 0.97361111 | L17: 0.6875 | M17: 46200 | N17: =IFERROR(M17/(O17*24), " ") -> 2701.7544 | O17: =(X17+W17)/2 -> 0.7125 | P17: =MOD(BD_PROD!$G17-BD_PROD!$E17,1) -> 0.74444444 | Q17: =MOD(BD_PROD!$H17-BD_PROD!$F17,1) -> 0.74791667 | R17: =(Q17+P17)/2 -> 0.74618056 | S17: =SUMIFS(BD_PARADAS[Tempo],BD_PARADAS[[Data ]],BD_PROD!$B17,BD_PARADAS[Setor],"Forno 1") + SUMIFS(BD_PARADAS[Tempo],BD_PARADAS[[Data ]],BD_PROD!$B17,BD_PARADAS[Setor],"Ensaque 1") -> 0.070138889 | T17: =SUMIFS(BD_PARADAS[Tempo],BD_PARADAS[[Data ]],BD_PROD!$B17,BD_PARADAS[Setor],"Forno 2") + SUMIFS(BD_PARADAS[Tempo],BD_PARADAS[[Data ]],BD_PROD!$B17,BD_PARADAS[Setor],"Ensaque 2") -> 0.13680556 | U17: =T17+S17 -> 0.20694444 | V17: =U17/2 -> 0.10347222 | W17: =MOD(J17-I17,1) -> 0.71111111 | X17: =MOD(L17-K17,1) -> 0.71388889 | Y17: =MOD(I17-D17,1) -> 0.080555556 | Z17: =MOD(K17-D17,1) -> 0.098611111 | AA17: =(Z17+Y17)/2 -> 0.089583333 | AB17: =AA17+V17 -> 0.19305556 | AC17: =BD_PROD!$AB17+BD_PROD!$O17 -> 0.90555556
B18: 46070 | C18: 61061 | D18: 0.875 | E18: 0.94444444 | F18: 0.94791667 | G18: 0.70694444 | H18: 0.7 | I18: 0.94513889 | J18: 0.71041667 | K18: 0.94861111 | L18: 0.68402778 | M18: 59950 | N18: =IFERROR(M18/(O18*24), " ") -> 3329.0143 | O18: =(X18+W18)/2 -> 0.75034722 | P18: =MOD(BD_PROD!$G18-BD_PROD!$E18,1) -> 0.7625 | Q18: =MOD(BD_PROD!$H18-BD_PROD!$F18,1) -> 0.75208333 | R18: =(Q18+P18)/2 -> 0.75729167 | S18: =SUMIFS(BD_PARADAS[Tempo],BD_PARADAS[[Data ]],BD_PROD!$B18,BD_PARADAS[Setor],"Forno 1") + SUMIFS(BD_PARADAS[Tempo],BD_PARADAS[[Data ]],BD_PROD!$B18,BD_PARADAS[Setor],"Ensaque 1") -> 0.024305556 | T18: =SUMIFS(BD_PARADAS[Tempo],BD_PARADAS[[Data ]],BD_PROD!$B18,BD_PARADAS[Setor],"Forno 2") + SUMIFS(BD_PARADAS[Tempo],BD_PARADAS[[Data ]],BD_PROD!$B18,BD_PARADAS[Setor],"Ensaque 2") -> 0 | U18: =T18+S18 -> 0.024305556 | V18: =U18/2 -> 0.012152778 | W18: =MOD(J18-I18,1) -> 0.76527778 | X18: =MOD(L18-K18,1) -> 0.73541667 | Y18: =MOD(I18-D18,1) -> 0.070138889 | Z18: =MOD(K18-D18,1) -> 0.073611111 | AA18: =(Z18+Y18)/2 -> 0.071875 | AB18: =AA18+V18 -> 0.084027778 | AC18: =BD_PROD!$AB18+BD_PROD!$O18 -> 0.834375
... B26: 46080 | C26: 30295 | D26: 0.875 | E26: 0.94236111 | F26: 0.94097222 | G26: 0.45833333 | H26: 0.26041667 | I26: 0.94375 | J26: 0.46527778 | K26: 0.94166667 | L26: 0.26041667 | M26: 33100 | N26: =IFERROR(M26/(O26*24), " ") -> 3282.6446 | O26: =(X26+W26)/2 -> 0.42013889 | P26: =MOD(BD_PROD!$G26-BD_PROD!$E26,1) -> 0.51597222 | Q26: =MOD(BD_PROD!$H26-BD_PROD!$F26,1) -> 0.31944444 | R26: =(Q26+P26)/2 -> 0.41770833 | S26: =SUMIFS(BD_PARADAS[Tempo],BD_PARADAS[[Data ]],BD_PROD!$B26,BD_PARADAS[Setor],"Forno 1") + SUMIFS(BD_PARADAS[Tempo],BD_PARADAS[[Data ]],BD_PROD!$B26,BD_PARADAS[Setor],"Ensaque 1") -> 0 | T26: =SUMIFS(BD_PARADAS[Tempo],BD_PARADAS[[Data ]],BD_PROD!$B26,BD_PARADAS[Setor],"Forno 2") + SUMIFS(BD_PARADAS[Tempo],BD_PARADAS[[Data ]],BD_PROD!$B26,BD_PARADAS[Setor],"Ensaque 2") -> 0 | U26: =T26+S26 -> 0 | V26: =U26/2 -> 0 | W26: =MOD(J26-I26,1) -> 0.52152778 | X26: =MOD(L26-K26,1) -> 0.31875 | Y26: =MOD(I26-D26,1) -> 0.06875 | Z26: =MOD(K26-D26,1) -> 0.066666667 | AA26: =(Z26+Y26)/2 -> 0.067708333 | AB26: =AA26+V26 -> 0.067708333 | AC26: =BD_PROD!$AB26+BD_PROD!$O26 -> 0.48784722
C27: =SUBTOTAL(109,C7:C26) -> 1062495 | M27: =SUBTOTAL(109,Tabela2[Qtd Produzida]) -> 976050 | N27: =SUBTOTAL(101,Tabela2[Tonelada/h]) -> 3233.5236 | O27: =SUBTOTAL(101,Tabela2[Prod Média]) -> 0.64440972 | P27: =SUBTOTAL(101,Tabela2[Tempo Prod F1]) -> 0.64961806 | Q27: =SUBTOTAL(101,Tabela2[Tempo Prod F2]) -> 0.67364583 | R27: =SUBTOTAL(101,Tabela2[Tempo Médio Produção Fornos]) -> 0.66163194 | V27: =SUBTOTAL(101,Tabela2[Média Paradas n prog]) -> 0.049565972 | W27: =SUBTOTAL(101,Tabela2[Produtividade Ens 1]) -> 0.63013889 | X27: =SUBTOTAL(101,Tabela2[Prod Ens 2]) -> 0.65868056 | AA27: =SUBTOTAL(101,Tabela2[Média de Start]) -> 0.076059028 | AB27: =SUBTOTAL(101,Tabela2[Tempo Parado]) -> 0.125625 | AC27: =SUBTOTAL(101,Tabela2[Carga Horária]) -> 0.77003472
M28: =SUM(BD_PROD!$M$7:$M$26) -> 976050
W36: 0.875 | X36: 0.71388889 | Y36: =MOD(X36-W36,1) -> 0.83888889 | Z36: =AC17-Y36 -> 0.066666667
C56: =SUM(BD_PROD!$C$7:$C$26) -> 1062495 | D56: =SUM(BD_PROD!$M$7:$M$26) -> 976050 | M56: =SUM(BD_PROD!$C$7:$C$26) -> 1062495

Sheet BD_PARADAS
B2: Data | C2: Setor | D2: Turno | E2: Causa | F2: Motivo | G2: Tempo | H2: Causa Raiz | I2: Total | J2: =SUBTOTAL(9,BD_PARADAS[Tempo]) -> 2.39375 | XFD2: =SUM(A2:XFC2) -> 2.39375
B3: 46072 | C3: Forno 1 | D3: 2° Turno | E3: Falta de massa | F3: Desarme da rosca R1 e R2, Desarme do picador | G3: 0.0375 | H3: Externa
B4: 46059 | C4: Extração | D4: 2° Turno | E4: Desarmerme da rosca Inclinada | F4: Correia escapou | G4: 0.026388889 | H4: Manutenção
B5: 46055 | C5: Descarga | D5: 2° Turno | E5: Aguardando raiz passar pelo raspador | F5: FAZ PARTE DO PROCESSO (NÃO ENTRA COMO PARADA) | G5: 0.010416667 | H5: Operacional
B6: 46055 | C6: Forno 2 | D6: 2° Turno | E6: Treinamento | F6: Falta de Planejamento | G6: 0.024305556 | H6: Operacional
B7: 46055 | C7: Forno 2 | D7: 2° Turno | E7: Troca de correia (Resfriador 1) | F7: Rosca de alimentação do resfriador escapou | G7: 0.020833333 | H7: Manutenção
B8: 46056 | C8: Forno 1 | D8: 1° Turno | E8: Falta de MP | F8: Chuva (Impactou na entrega das cargas) | G8: 0.39097222 | H8: Externa
B9: 46079 | C9: Forno 2 | D9: 2° Turno | E9: Falta de Massa | F9: Falta de massa no forno, filtro não conseguiu acompanhar a velocidade | G9: 0.01875 | H9: Operacional
B10: 46058 | C10: Ensaque 2 | D10: 1° Turno | E10: Moinho Desarmado | F10: Carolo entupindo moinho | G10: 0.010416667 | H10: Operacional
B11: 46058 | C11: Forno 2 | D11: 1° Turno | E11: Moinho entupido (Saida F1) | F11: Pico de energia | G11: 0.0041666667 | H11: Elétrica
B12: 46058 | C12: Forno 2 | D12: 1° Turno | E12: Pico de energia | F12: N/A | G12: 0.0034722222 | H12: Elétrica
B13: 46058 | C13: Forno 1 | D13: 1° Turno | E13: Pico de energia | F13: N/A | G13: 0.0034722222 | H13: Elétrica
B14: 46069 | C14: Extração | D14: 2° Turno | E14: Queima do relé (Filtro 2) | F14: Tempo de uso | G14: 0.021527778 | H14: Manutenção
... B20: 46064 | C20: Forno 1 | D20: 1° Turno | E20: Revesamento | F20: Falta de Pessoas (Direcionamento para o Silo) | G20: 0.052083333 | H20: Operacional
B21: 46064 | C21: Forno 1 | D21: 1° Turno | E21: Falta de MP | F21: Atraso na chegada da carga (Redução de velocidade da linha) | H21: Externa
B22: 46065 | C22: Forno 1 | D22: 1° Turno | E22: Falta de MP | F22: Atraso de chegada da carga (Faltou uma carga no dia, por conta da chuva) | G22: 0.23958333 | H22: Externa
B23: 46069 | C23: Forno 2 | D23: 1° Turno | E23: Falta de Massa | F23: Picador entupide e Barra roscada solta | G23: 0.13541667 | H23: Manutenção
B24: 46069 | C24: Forno 1 | D24: 1° Turno | E24: Revesamento | F24: Falta de Pessoas (Direcionamento para o Silo) | G24: 0.06875 | H24: Operacional
B25: 46072 | C25: Extração | D25: 2° Turno | E25: Desarme da rosca R1 e R2 | F25: Entupimento da rosca intercepitadora (desarme) | G25: 0.019444444 | H25: Operacional | K25: 3028
B26: 46072 | C26: Extração | D26: 2° Turno | E26: Desarme do picador | F26: Parou com raiz dentro do máquinario (falha elétrica) | G26: 0.0083333333 | H26: Operacional | K26: 2422
B27: 46069 | C27: Extração | D27: 1° Turno | E27: Rosca solta e Rapador 01 entupido | F27: Barra roscada danpeneira vibratória soltou, causando entupimento do rapador 1 | G27: 0.059722222 | H27: Manutenção | K27: 40.37
B28: 46069 | C28: Extração | D28: 1° Turno | E28: Picador entupido | F28: automação de parada por nivel | G28: 0.036111111 | H28: Manutenção
B29: 46069 | C29: Forno 1 | D29: 1° Turno | E29: Pico de energia | F29: N/A | G29: 0.0013888889 | H29: Elétrica
B30: 46069 | C30: Forno 2 | D30: 1° Turno | E30: Pico de energia | F30: N/A | G30: 0.0013888889 | H30: Elétrica
B31: 46070 | C31: Ensaque 1 | D31: 1° Turno | E31: Rosca Inclinada | F31: Excesso na caixa do ensaque 1 | G31: 0.024305556 | H31: Operacional
B32: 46070 | C32: Extração | D32: 1° Turno | E32: Filtro Travado | F32: Prensa não estava pressurizando | G32: 0.024305556 | H32: Operacional | J32: 0.36180556 | K32: 0.36458333
B33: 46070 | C33: N/A | D33: 1° Turno | E33: Falta de MP | F33: Atraso na chegada da carga (Redução de velocidade da linha) | G33: 0.027777778 | H33: Externa | J33: 0.46666667 | K33: 0.57986111
B34: 46071 | C34: Forno 2 | D34: 1° Turno | E34: Falta de MP | G34: 0.11041667 | H34: Externa | J34: =J33-J32 -> 0.10486111 | K34: =K33-K32 -> 0.21527778
B35: 46071 | C35: Forno 2 | D35: 1° Turno | E35: Falta de Massa | F35: Erro operacional (Falta de Prensa) | G35: 0.10486111 | H35: Operacional | K35: =K34-J34 -> 0.11041667
B36: 46071 | C36: Extração | D36: 1° Turno | E36: Picador entupido | F36: automação de parada por nivel | G36: 0.013194444 | H36: Manutenção
B37: 46071 | C37: Extração | D37: 1° Turno | E37: Rosca do vibrador travada | F37: Falta de água (Manutenção externa) | G37: 0.029166667 | H37: Externa
B38: 46071 | C38: Extração | D38: 1° Turno | E38: Raspador travado | F38: Motor pesou e travou | G38: 0.021527778 | H38: Operacional
B39: 46072 | C39: Forno 2 | D39: 1° Turno | E39: Falta de MP | G39: 0.22361111 | H39: Externa
B40: 46077 | C40: Extração | D40: 2° Turno | E40: Travamento do Moinho | F40: Falha qundo foi realizar o desligamento dos maquinarios (Não seguiu a ordem correta) | G40: 0.0076388889 | H40: Operacional
B41: 46055 | C41: Extração | D41: 2° Turno | E41: Montagem do equipamento | F41: Não foi realizado após a Limpeza | G41: 0.0069444444 | H41: Operacional
B42: 46079 | C42: Forno 2 | D42: 2° Turno | E42: Travamento do Moinho | F42: Carolo entupindo moinho | G42: 0.0034722222 | H42: Operacional
B43: 46072 | C43: Extração | D43: 1° Turno | E43: Moinho do picador travado | F43: Desligou os equipamnetos com raiz no picador | G43: 0.01875 | H43: Operacional
B44: 46076 | C44: Forno 1 | D44: 2° Turno | E44: Pico de energia | F44: N/A | G44: 0.0020833333 | H44: Elétrica
B45: 46076 | C45: Forno 2 | D45: 2° Turno | E45: Pico de energia | F45: N/A | G45: 0.0020833333 | H45: Elétrica
B46: 46077 | C46: Forno 1 | D46: 1° Turno | E46: Pico de energia | F46: N/A | G46: 0.00625 | H46: Elétrica
...

Sheet RELATÓRIO_EFIC
B2: Indicadores | C2: Ruim | D2: Regular | E2: Bom
B3: Produtividade | C3: 0.8 | D3: ="Entre "&C3*100&"% "&E3*100&"%" -> Entre 80% 90% | E3: 0.9
B4: Tempo de fábrica | C4: 0.7 | D4: ="Entre "&C4*100&"% "&E4*100&"%" -> Entre 70% 85% | E4: 0.85
B5: Maquinário | C5: 0.6 | D5: ="Entre "&C5*100&"% "&E5*100&"%" -> Entre 60% 80% | E5: 0.8
B7: Eficiência do Período
B8: Data Inicial | C8: 46023
B9: Data Final | C9: 46053
B10: Período | C10: =B4 -> Tempo de fábrica | D10: =B3 -> Produtividade | E10: =B5 -> Maquinário
B11: =C9-C8 -> 30 | C11: =GETPIVOTDATA("Tempo Fábrica",$B$14) -> 0.84464672 | D11: =GETPIVOTDATA("Produtividade.",$B$14) -> 0.91863962 | E11: =GETPIVOTDATA("Maquinário",$B$14) -> 0.77592594
B13: Eficiência Diária
B14: Data | C14: Tempo Fábrica | D14: Produtividade. | E14: Maquinário
B15: 46055 | C15: 0.8017714 | D15: 0.71240235 | E15: 0.57118383
B16: 46056 | C16: 0.69233904 | D16: 0.7664749 | E16: 0.5306605
B17: 46057 | C17: 0.91116974 | D17: 0.88568913 | E17: 0.80701314
B18: 46058 | C18: 0.90379009 | D18: 1.013172 | E18: 0.9156948
B19: 46059 | C19: 0.84785714 | D19: 0.94284196 | E19: 0.79939529
B20: 46062 | C20: 0.86010573 | D20: 0.83152695 | E20: 0.7152011
B21: 46063 | C21: 0.91361702 | D21: 0.95981079 | E21: 0.87689947
B22: 46064 | C22: 0.88797702 | D22: 0.97447838 | E22: 0.86531441
B23: 46065 | C23: 0.77154989 | D23: 0.84797037 | E23: 0.65425145
B24: 46066 | C24: 0.8594088 | D24: 0.99850969 | E24: 0.85812801
B25: 46069 | C25: 0.78680982 | D25: 0.75662043 | E25: 0.59531638
B26: 46070 | C26: 0.89929255 | D26: 0.98180508 | E26: 0.88293
... B34: 46080 | C34: 0.86120996 | D34: 1.0925895 | E34: 0.940949
B35: Total Geral | C35: 0.84464672 | D35: 0.91863962 | E35: 0.77592594
B40: Data | C40: =B4 -> Tempo de fábrica | D40: =B3 -> Produtividade | E40: =B5 -> Maquinário
B41: {=CHOOSE({1,2,3,4},BD_PROD!$B$7:$B$26,BD_PROD!$O$7:$O$26/BD_PROD!$AC$7:$AC$26,BD_PROD!$M$7:$M$26/BD_PROD!$C$7:$C$26,(BD_PROD!$O$7:$O$26/BD_PROD!$AC$7:$AC$26)*(BD_PROD!$M$7:$M$26/BD_PROD!$C$7:$C$26))} -> 46055 | C41: 0.80653373 | D41: 0.71240235 | E41: 0.57457653
B42: 46056 | C42: 0.69233904 | D42: 0.7664749 | E42: 0.5306605
B43: 46057 | C43: 0.91116974 | D43: 0.88568913 | E43: 0.80701314
B44: 46058 | C44: 0.90379009 | D44: 1.013172 | E44: 0.9156948
B45: 46059 | C45: 0.84785714 | D45: 0.94284196 | E45: 0.79939529
B46: 46062 | C46: 0.86010573 | D46: 0.83152695 | E46: 0.7152011
B47: 46063 | C47: 0.91361702 | D47: 0.95981079 | E47: 0.87689947
B48: 46064 | C48: 0.88797702 | D48: 0.97447838 | E48: 0.86531441
B49: 46065 | C49: 0.77154989 | D49: 0.84797037 | E49: 0.65425145
B50: 46066 | C50: 0.8594088 | D50: 0.99850969 | E50: 0.85812801
B51: 46069 | C51: 0.78680982 | D51: 0.75662043 | E51: 0.59531638
B52: 46070 | C52: 0.89929255 | D52: 0.98180508 | E52: 0.88293
B53: 46071 | C53: 0.81119403 | D53: 0.77794648 | E53: 0.63106554
... B60: 46080 | C60: 0.86120996 | D60: 1.0925895 | E60: 0.940949
